Workbook

Sheet Review
A1: 200V migration: items for review
A2: Set a Decision for each item and add comments. Item details are on the other tabs.
A4: # | B4: Section | C4: Switch | D4: Port | E4: Item | F4: Evidence | G4: Proposed action | H4: Decision | I4: Comments
B5: 1. Device list: ports filled in by script
A6: 1 | B6: 1 | C6: switch-200V-LT2-1 | D6: 1/1/6 | E6: AV: PDU (master row 1068) | F6: Master list lookup failed (N/A). MAC B8-80-4F-28-58-24 found on this port in the 200V tab (1230 (200V_av)) | G6: Accept port; move 1230 (200V_av) -> 2700 (VL-av-01) | H6: Approve | I6: Moved to 2700 in the 9 Oct cutover
A7: 2 | B7: 1 | C7: switch-200V-LT2-1 | D7: 1/1/7 | E7: AV: Recorder (master row 1215) | F7: Master list lookup failed (N/A). MAC 00-1C-08-00-6C-7C found on this port in the 200V tab (1230 (200V_av)) | G7: Accept port; move 1230 (200V_av) -> 2700 (VL-av-01) | H7: Approve | I7: Moved to 2700 in the 9 Oct cutover
A8: 3 | B8: 1 | C8: switch-200V-LT2-1 | D8: 1/1/8 | E8: AV: Audio DSP (master row 759) | F8: Master list lookup failed (N/A). MAC 78-45-01-0C-7D-3A found on this port in the 200V tab (1230 (200V_av)). Also confirmed by LLDP on 6 Oct | G8: Accept port; move 1230 (200V_av) -> 2700 (VL-av-01) | H8: Approve | I8: Moved to 2700 in the 9 Oct cutover
A9: 4 | B9: 1 | C9: switch-200V-LT2-1 | D9: 1/1/10 | E9: AV: LCD 2 (master row 910) | F9: Master list lookup failed (N/A). MAC A8-4A-63-30-73-66 found on this port in the 200V tab (1230 (200V_av)) | G9: Accept port; move 1230 (200V_av) -> 2700 (VL-av-01) | H9: Approve | I9: Moved to 2700 in the 9 Oct cutover
A10: 5 | B10: 1 | C10: switch-200V-LT2-1 | D10: 1/1/11 | E10: AV: LCD 1 (master row 909) | F10: Master list lookup failed (N/A). MAC A8-4A-63-30-73-67 found on this port in the 200V tab (1230 (200V_av)) | G10: Accept port; move 1230 (200V_av) -> 2700 (VL-av-01) | H10: Approve | I10: Moved to 2700 in the 9 Oct cutover
A11: 6 | B11: 1 | C11: switch-200V-LT2-1 | D11: 1/1/12 | E11: AV: PTZ Camera (master row 1204) | F11: Master list lookup failed (N/A). MAC DC-E2-AC-02-E4-F5 found on this port in the 200V tab (1230 (200V_av)) | G11: Accept port; move 1230 (200V_av) -> 2700 (VL-av-01) | H11: Approve | I11: Moved to 2700 in the 9 Oct cutover
A12: 7 | B12: 1 | C12: switch-200V-LT2-1 | D12: 1/1/13 | E12: AV: Room Camera (master row 1253) | F12: Master list lookup failed (N/A). MAC B8-A4-4F-69-B2-72 found on this port in the 200V tab (1230 (200V_av)). Also confirmed by LLDP on 6 Oct | G12: Accept port; move 1230 (200V_av) -> 2700 (VL-av-01) | H12: Approve | I12: Moved to 2700 in the 9 Oct cutover
A13: 8 | B13: 1 | C13: switch-200V-LT2-1 | D13: 1/1/14 | E13: AV: Occupancy Sensor (master row 957) | F13: Master list lookup failed (N/A). MAC B8-98-B0-0F-1C-66 found on this port in the 200V tab (1230 (200V_av)) | G13: Accept port; move 1230 (200V_av) -> 2700 (VL-av-01) | H13: Approve | I13: Moved to 2700 in the 9 Oct cutover
A14: 9 | B14: 1 | C14: switch-200V-LT2-1 | D14: 1/1/15 | E14: AV: Projector Screen 2 (master row 1195) | F14: Master list lookup failed (N/A). MAC 04-91-62-D7-70-0D found on this port in the 200V tab (1230 (200V_av)) | G14: Accept port; move 1230 (200V_av) -> 2700 (VL-av-01) | H14: Approve | I14: Moved to 2700 in the 9 Oct cutover; device not yet seen on 2700 (AV team check, item 99)
A15: 10 | B15: 1 | C15: switch-200V-LT2-1 | D15: 1/1/16 | E15: AV: Projector Screen 1 (master row 1194) | F15: Master list lookup failed (N/A). MAC 54-10-EC-A2-E8-27 found on this port in the 200V tab (1230 (200V_av)) | G15: Accept port; move 1230 (200V_av) -> 2700 (VL-av-01) | H15: Approve | I15: Moved to 2700 in the 9 Oct cutover; device not yet seen on 2700 (AV team check, item 100)
A16: 11 | B16: 1 | C16: switch-200V-LT2-1 | D16: 1/1/17 | E16: AV: Projector 1 (master row 1176) | F16: Master list lookup failed (N/A). MAC 38-1A-52-B1-75-B6 found on this port in the 200V tab (1230 (200V_av)) | G16: Accept port; move 1230 (200V_av) -> 2700 (VL-av-01) | I16: Moved to 2700 in the 9 Oct cutover; no decision recorded on the Review tab before the cutover
A17: 12 | B17: 1 | C17: switch-200V-LT2-1 | D17: 1/1/18 | E17: AV: Projector 2 (master row 1180) | F17: Master list lookup failed (N/A). MAC 38-1A-52-B1-74-BA found on this port in the 200V tab (1230 (200V_av)) | G17: Accept port; move 1230 (200V_av) -> 2700 (VL-av-01) | H17: Approve | I17: Moved to 2700 in the 9 Oct cutover
A18: 13 | B18: 1 | C18: switch-200V-LT2-1 | D18: 1/1/20 | E18: AV: Touch Panel (master row 1339) | F18: Master list lookup failed (N/A). MAC C4-42-68-26-D6-48 found on this port in the 200V tab (1230 (200V_av)). Also confirmed by LLDP on 6 Oct | G18: Accept port; move 1230 (200V_av) -> 2700 (VL-av-01) | H18: Approve | I18: Moved to 2700 in the 9 Oct cutover
A19: 14 | B19: 1 | C19: switch-200V-stack-lv6 | D19: 4/1/24 | E19: PhysicalAccess: cloe-000-200v (master row 1686) | F19: Master list lookup failed (N/A). MAC 00:11:B9:08:2B:67 found on this port in the 200V tab (1213 (200V_building)) | G19: Accept port; move 1213 (200V_building) -> 2510 (VL-bac-01) | H19: Approve | I19: Moved to 2510 in the 9 Oct cutover
B20: 2. Devices not found on any switch
A21: 15 | B21: 2 | E21: AP: r650-39-4d-10 (master row 475), MAC C8:A6:08:39:4D:10 | F21: MAC not in the 200V tab | G21: Find on site
A22: 16 | B22: 2 | C22: switch-200V-Tutorial-6.03 | D22: 1/1/9 | E22: AV Switcher (master row 769) | F22: 200V tab has 01d.560a.dfc0 on Tutorial-6.03 1/1/9 (same MAC, leading zero lost). Port is untagged 1230. 6 Oct: core sees 001d.560a.dfc0 live on VLAN 1230 behind Tutorial-6.03 (lag 6) | G22: Find on site
A23: 17 | B23: 2 | E23: AV: AV Switcher (master row 779), MAC 00-1D-56-0A-B4-AB | F23: MAC not in the 200V tab | G23: Find on site
A24: 18 | B24: 2 | E24: AV: Projector (master row 1121), MAC F8:25:51:72:A4:52 | F24: MAC not in the 200V tab | G24: Find on site
A25: 19 | B25: 2 | C25: switch-200V-8 | D25: 1/1/6 (likely) | E25: AV: Projector (master row 1134), MAC F8:25:51:CB:8C:94 | F25: MAC not in the 200V tab. 6 Oct: core sees f825.51cb.8c94 on VLAN 1230 behind switch-200V-8 (lag 4). 1/1/6 is the only port untagged in 1230 on that switch | G25: Find on site
A26: 20 | B26: 2 | E26: AV: Projector (master row 1145), MAC F8:25:51:CC:0F:C6 | F26: MAC not in the 200V tab | G26: Find on site
B27: 3. Ports with a device seen but none listed
A28: 21 | B28: 3 | C28: switch-200V-LT2-1 | D28: 1/1/9 | E28: Unlisted device | F28: MAC 00:50:56:05:43:F1 seen in 200V tab; port untagged 1230 (200V_av). 00:50:56 is a VMware virtual MAC | G28: Identify device
A29: 22 | B29: 3 | C29: switch-200V-LT2-1 | D29: 1/1/21 | E29: Unlisted device | F29: MAC 48:21:0B:56:AC:A4 seen in 200V tab; port untagged 1240 (200V_staff). LLDP: CLA-TAN3130059J (NUC, MAC 48:21:0B:56:AC:A4), not in device list | G29: Identify device
A30: 23 | B30: 3 | C30: switch-200V-LT2-3 | D30: 1/1/4 | E30: Unlisted device | F30: MAC d4:a2:cd:e1:dd:0e seen in 200V tab; port untagged 1240 (200v_staff) | G30: Identify device | H30: Done | I30: VL-staff-wired-01 - 2100 | Moved 9 Oct; link down (nothing connected on LT2-3)
A31: 24 | B31: 3 | C31: switch-200V-Tutorial-6.03 | D31: 1/1/3 | E31: Unlisted device | F31: MAC F8:25:51:CB:8C:76 seen in 200V tab; port untagged 1230 | G31: Identify device
A32: 25 | B32: 3 | C32: switch-200V-stack-lv3 | D32: 1/1/48 | E32: Unlisted device | F32: MAC 00:09:F5:32:DB:49 seen in 200V tab; port untagged 100 (management) | G32: Identify device | I32: 2000 10.21.0.0/24 VL-netmgmt-01 | NOT moved: left on 100. Device live (0009.f532.db49); addressing unknown. Confirm DHCP or re-address into 10.21.0.0/24 before moving to 2000
A33: 26 | B33: 3 | C33: switch-200V-stack-lv3 | D33: 2/1/16 | E33: Unlisted device | F33: MAC D8:43:AE:B1:69:BE seen in 200V tab; port untagged 1230 (200V_av) | G33: Move 1230 -> 2700 with the rest of the room AV (config in 200V-av-unlisted-2700-ICX.txt) | H33: Done | I33: Moved 1230 -> 2700 on 9 Oct (200V-av-unlisted-2700-ICX.txt)
A34: 27 | B34: 3 | C34: switch-200V-stack-lv3 | D34: 2/1/29 | E34: Unlisted device | F34: MAC D8:43:AE:B1:6E:9B seen in 200V tab; port untagged 1230 (200V_av) | G34: Move 1230 -> 2700 with the rest of the room AV (config in 200V-av-unlisted-2700-ICX.txt) | H34: Done | I34: Moved 1230 -> 2700 on 9 Oct (200V-av-unlisted-2700-ICX.txt)
A35: 28 | B35: 3 | C35: switch-200V-stack-lv3 | D35: 3/1/5 | E35: Unlisted device | F35: MAC 4C:C5:D9:D0:8D:2A seen in 200V tab; port untagged 1240 (200V_staff) | G35: Identify device | H35: Done | I35: VL-staff-wired-01 - 2100 | Moved 9 Oct; link down
A36: 29 | B36: 3 | C36: switch-200V-stack-lv3 | D36: 3/1/29 | E36: Unlisted device | F36: MAC D8:3A:DD:C6:37:A8 seen in 200V tab; port untagged 230 (Library) | G36: Identify device | H36: Done | I36: 2530(vl-library-01) | Moved 9 Oct; MAC learned on 2530
A37: 30 | B37: 3 | C37: switch-200V-stack-lv3 | D37: 3/1/31 | E37: Unlisted device | F37: MAC D0:C1:B5:21:B3:20 seen in 200V tab; port untagged 1240 (200V_staff) | G37: Identify device | H37: Done | I37: VL-staff-wired-01 - 2100 | Moved 9 Oct; link down
A38: 31 | B38: 3 | C38: switch-200V-stack-lv3 | D38: 3/1/33 | E38: Unlisted device | F38: MAC 1C:1A:DF:C2:45:23 seen in 200V tab; port untagged 1240 (200V_staff) | G38: Identify device | H38: Done | I38: VL-staff-wired-01 - 2100 | Moved 9 Oct; link up, no MAC yet (device idle, 0 packets in)
A39: 32 | B39: 3 | C39: switch-200V-stack-lv3 | D39: 3/1/43 | E39: Unlisted device | F39: MAC 1C:1A:DF:C2:45:39 seen in 200V tab; port untagged 1240 (200V_staff) | G39: Identify device | H39: Done | I39: VL-staff-wired-01 - 2100 | Moved 9 Oct; link up, no MAC yet (device idle)
A40: 33 | B40: 3 | C40: switch-200V-stack-lv3 | D40: 4/1/28 | E40: Unlisted device | F40: MAC AC:B4:80:F1:61:85 seen in 200V tab; port untagged 1240 (200V_staff) | G40: Identify device | H40: Done | I40: VL-staff-wired-01 - 2100 | Moved 9 Oct; link down
A41: 34 | B41: 3 | C41: switch-200V-stack-lv3 | D41: 4/1/29 | E41: Unlisted device | F41: MAC 2C:CF:67:A6:4B:DE seen in 200V tab; port untagged 230 (Library) | G41: Identify device | H41: Done | I41: 2530(vl-library-01) | Moved 9 Oct; MAC learned on 2530
...

Sheet Old VLAN ports 10 Oct
A1: Ports still untagged on an old VLAN, from show interfaces brief on 10 Oct 2026 (lv3, lv4, lv6; lv6 1240 ports re-checked after units 3 and 4 rejoined). Pvid 1, uplinks and stack ports are left out.
A3: Switch | B3: Port | C3: Link | D3: Speed | E3: Tagged | F3: Old VLAN | G3: Suggested new VLAN | H3: Review item | I3: Notes | J3: MAC seen 10 Oct
A4: lv3 | B4: 1/1/12 | C4: Down | E4: Yes | F4: 100 (management) | G4: AP-style port (tagged VLANs) | H4: 65
A5: lv3 | B5: 1/1/34 | C5: Down | E5: No | F5: 1230 (200V_av) | G5: 2700 (VL-av-01)
A6: lv3 | B6: 1/1/48 | C6: Up | D6: 100M | E6: No | F6: 100 (management) | G6: 2000 (VL-netmgmt-01) once addressing is confirmed | H6: 25, 109 | I6: MAC seen 6 Oct: 00:09:F5:32:DB:49 | J6: 0009.f532.db49
A7: lv3 | B7: 2/1/14 | C7: Down | E7: No | F7: 1230 (200V_av) | G7: 2700 (VL-av-01)
A8: lv3 | B8: 2/1/24 | C8: Down | E8: No | F8: 1230 (200V_av) | G8: 2700 (VL-av-01) | H8: 111
A9: lv3 | B9: 2/1/27 | C9: Down | E9: No | F9: 1230 (200V_av) | G9: 2700 (VL-av-01)
A10: lv3 | B10: 2/1/34 | C10: Down | E10: No | F10: 1230 (200V_av) | G10: 2700 (VL-av-01)
A11: lv3 | B11: 3/1/3 | C11: Down | E11: No | F11: 1240 (200V_staff) | G11: 2100 (VL-staff-wired-01)
A12: lv3 | B12: 3/1/7 | C12: Down | E12: No | F12: 1240 (200V_staff) | G12: 2100 (VL-staff-wired-01)
A13: lv3 | B13: 3/1/10 | C13: Up | D13: 1G | E13: No | F13: 1240 (200V_staff) | G13: 2100 (VL-staff-wired-01)
A14: lv3 | B14: 3/1/11 | C14: Up | D14: 1G | E14: No | F14: 1240 (200V_staff) | G14: 2100 (VL-staff-wired-01)
A15: lv3 | B15: 3/1/13 | C15: Up | D15: 1G | E15: No | F15: 1240 (200V_staff) | G15: 2100 (VL-staff-wired-01)
A16: lv3 | B16: 3/1/15 | C16: Down | E16: No | F16: 1240 (200V_staff) | G16: 2100 (VL-staff-wired-01)
A17: lv3 | B17: 3/1/16 | C17: Down | E17: No | F17: 1240 (200V_staff) | G17: 2100 (VL-staff-wired-01)
A18: lv3 | B18: 3/1/19 | C18: Down | E18: No | F18: 1240 (200V_staff) | G18: 2100 (VL-staff-wired-01)
A19: lv3 | B19: 3/1/20 | C19: Up | D19: 1G | E19: No | F19: 1240 (200V_staff) | G19: 2100 (VL-staff-wired-01) | I19: Moved to 2100 on 10 Oct. | J19: 1c1a.dfc2.5143
A20: lv3 | B20: 3/1/27 | C20: Down | E20: No | F20: 1240 (200V_staff) | G20: 2100 (VL-staff-wired-01)
A21: lv3 | B21: 3/1/28 | C21: Down | E21: No | F21: 230 (Library) | G21: 2530 (VL-library-01) - check | H21: 71
A22: lv3 | B22: 4/1/2 | C22: Down | E22: No | F22: 1240 (200V_staff) | G22: 2100 (VL-staff-wired-01)
A23: lv3 | B23: 4/1/23 | C23: Down | E23: No | F23: 1240 (200V_staff) | G23: 2100 (VL-staff-wired-01)
A24: lv3 | B24: 4/1/24 | C24: Down | E24: No | F24: 1240 (200V_staff) | G24: 2100 (VL-staff-wired-01)
A25: lv3 | B25: 4/1/25 | C25: Down | E25: No | F25: 1240 (200V_staff) | G25: 2100 (VL-staff-wired-01)
A26: lv3 | B26: 4/1/26 | C26: Down | E26: No | F26: 1240 (200V_staff) | G26: 2100 (VL-staff-wired-01)
A27: lv3 | B27: 4/1/27 | C27: Down | E27: No | F27: 1240 (200V_staff) | G27: 2100 (VL-staff-wired-01)
A28: lv3 | B28: 4/1/45 | C28: Down | E28: No | F28: 1230 (200V_av) | G28: 2700 (VL-av-01)
A29: lv3 | B29: 5/1/4 | C29: Down | E29: No | F29: 1230 (200V_av) | G29: 2700 (VL-av-01)
A30: lv3 | B30: 5/1/5 | C30: Down | E30: No | F30: 1230 (200V_av) | G30: 2700 (VL-av-01)
A31: lv3 | B31: 5/1/6 | C31: Down | E31: No | F31: 1230 (200V_av) | G31: 2700 (VL-av-01)
A32: lv3 | B32: 5/1/7 | C32: Down | E32: No | F32: 1230 (200V_av) | G32: 2700 (VL-av-01)
A33: lv3 | B33: 5/1/13 | C33: Down | E33: No | F33: 1230 (200V_av) | G33: 2700 (VL-av-01)
... A37: lv3 | B37: 5/1/43 | C37: Down | E37: No | F37: 1230 (200V_av) | G37: 2700 (VL-av-01)
A38: lv4 | B38: 1/1/8 | C38: Down | E38: Yes | F38: 100 (management) | G38: AP-style port (tagged VLANs) | H38: 66
A39: lv4 | B39: 1/1/17 | C39: Down | E39: No | F39: 1230 (200V_av) | G39: 2700 (VL-av-01)
A40: lv4 | B40: 1/1/32 | C40: Down | E40: No | F40: 1230 (200V_av) | G40: 2700 (VL-av-01)
A41: lv4 | B41: 1/1/48 | C41: Up | D41: 100M | E41: No | F41: 100 (management) | G41: 2000 (VL-netmgmt-01) once addressing is confirmed | H41: 43, 109 | I41: MAC seen 6 Oct: 00:09:F5:32:D9:F7 | J41: 0009.f532.d9f7
A42: lv4 | B42: 2/1/8 | C42: Down | E42: No | F42: 1212 (200V_IPcam) | G42: 2600 (VL-cctv-01) | H42: 64
A43: lv4 | B43: 2/1/18 | C43: Down | E43: No | F43: 1230 (200V_av) | G43: 2700 (VL-av-01)
A44: lv4 | B44: 2/1/20 | C44: Down | E44: No | F44: 1230 (200V_av) | G44: 2700 (VL-av-01)
...

Sheet 200V Devices
A1: Master row | B1: Type | C1: Device | D1: MAC | E1: Switch name | F1: Port | G1: Old VLAN | H1: New VLAN | I1: Status | J1: Port source
A2: 469 | B2: AP | C2: r650-39-49-a0 | D2: C8:A6:08:39:49:A0 | E2: switch-200V-LT2-1 | F2: 1/1/1 | G2: 100 (management) | H2: 2010 (VL-wifimgmt-01) | I2: Done | J2: Master list
A3: 1104 | B3: AV | C3: Pro convert for NDI to HDMI | D3: D0:C8:57:81:64:24 | E3: switch-200V-LT2-1 | F3: 1/1/4 | G3: 1230 (200V_av) | H3: 2700 (VL-av-01) | I3: Done | J3: Master list
A4: 708 | B4: AV | C4: Airtame | D4: 38:4b:76:f1:8f:ec | E4: switch-200V-LT2-1 | F4: 1/1/5 | G4: 1272 (200V_w_wifi) | H4: 2700 (VL-av-01) | I4: Done | J4: Master list
A5: 1068 | B5: AV | C5: PDU | D5: B8-80-4F-28-58-24 | E5: switch-200V-LT2-1 | F5: 1/1/6 | G5: 1230 (200V_av) | H5: 2700 (VL-av-01) | I5: Done | J5: Matched from 200V tab
A6: 1215 | B6: AV | C6: Recorder | D6: 00-1C-08-00-6C-7C | E6: switch-200V-LT2-1 | F6: 1/1/7 | G6: 1230 (200V_av) | H6: 2700 (VL-av-01) | I6: Done | J6: Matched from 200V tab
A7: 759 | B7: AV | C7: Audio DSP | D7: 78-45-01-0C-7D-3A | E7: switch-200V-LT2-1 | F7: 1/1/8 | G7: 1230 (200V_av) | H7: 2700 (VL-av-01) | I7: Done | J7: Matched from 200V tab
A8: 910 | B8: AV | C8: LCD 2 | D8: A8-4A-63-30-73-66 | E8: switch-200V-LT2-1 | F8: 1/1/10 | G8: 1230 (200V_av) | H8: 2700 (VL-av-01) | I8: Done | J8: Matched from 200V tab
A9: 909 | B9: AV | C9: LCD 1 | D9: A8-4A-63-30-73-67 | E9: switch-200V-LT2-1 | F9: 1/1/11 | G9: 1230 (200V_av) | H9: 2700 (VL-av-01) | I9: Done | J9: Matched from 200V tab
A10: 1204 | B10: AV | C10: PTZ Camera | D10: DC-E2-AC-02-E4-F5 | E10: switch-200V-LT2-1 | F10: 1/1/12 | G10: 1230 (200V_av) | H10: 2700 (VL-av-01) | I10: Done | J10: Matched from 200V tab
A11: 1253 | B11: AV | C11: Room Camera | D11: B8-A4-4F-69-B2-72 | E11: switch-200V-LT2-1 | F11: 1/1/13 | G11: 1230 (200V_av) | H11: 2700 (VL-av-01) | I11: Done | J11: Matched from 200V tab
A12: 957 | B12: AV | C12: Occupancy Sensor | D12: B8-98-B0-0F-1C-66 | E12: switch-200V-LT2-1 | F12: 1/1/14 | G12: 1230 (200V_av) | H12: 2700 (VL-av-01) | I12: Done | J12: Matched from 200V tab
A13: 1195 | B13: AV | C13: Projector Screen 2 | D13: 04-91-62-D7-70-0D | E13: switch-200V-LT2-1 | F13: 1/1/15 | G13: 1230 (200V_av) | H13: 2700 (VL-av-01) | I13: Done | J13: Matched from 200V tab
... A393: 1111 | B393: AV | C393: Projector | D393: 38:1A:52:B1:75:B8 | E393: switch-200V-stack-lv6 | F393: 7/1/44 | G393: 1230 (200V_av) | H393: 2700 (VL-av-01) | I393: Done | J393: Master list

Sheet Switches
A1: Hostname | B1: Role | C1: Hardware | D1: Config file (by MAC) | E1: Uplink to core | F1: 200V devices | G1: To do | H1: Management IP | I1: 9 Oct 2026 result | J1: 26 Oct 2026 result
A2: trinity200V-core | B2: Core / gateway for new VLANs | C2: 2 x ICX8200-24FX stack | D2: B0_7C_51_1F_8C_06 | E2: n/a | F2: n/a | G2: n/a | H2: 10.20.8.2 (ve 1960) | I2: Reloaded for system-max 40. WIFIMGMT-IN ACL: added seq 23/24 (SmartZone private IPs) and seq 25 (RADIUS 10.128.131.7) - unplanned, see Review 91 and 107. Saved | J2: Not changed (ve 2000 10.21.0.1 is the gateway for the switch management addresses)
A3: switch-200V-stack-lv3 | B3: Access | C3: 5 x ICX8200 stack | D3: 80_F0_CF_38_0D_C2 | E3: lag 3 (lvl3) | F3: =COUNTIF('200V Devices'!E2:E393,A3) -> 93 | G3: =COUNTIFS('200V Devices'!E2:E393,A3,'200V Devices'!I2:I393,"To do") -> 0 | H3: 10.21.0.27 (ve 2000, VLAN 2000), from 26 Oct; was 192.168.122.22 (ve 100) | I3: Cutover done, 84 ports. system-max 40 active. Review tab change: 7 ports (5 to 2100, 2 to 2530). Saved. 1/1/48 left on 100. Unlisted AV: 8 ports 1230 -> 2700. 10 Oct: 7 outlets (20:7B:D2:30 devices) 1230 -> 2100. 10 Oct: 3/1/20 (staff PC) 1240 -> 2100 | J3: Port clean-up: 32 ports (Trinity column Q, 16 Oct export). Management moved to 10.21.0.27, default route via 10.21.0.1, management source ve 2000, old IP removed. Saved. First Part B attempt rolled back by the reload timer (7:06 pm); second attempt OK.
A4: switch-200V-stack-lv4 | B4: Access | C4: 5 x ICX8200 stack | D4: 80_F0_CF_37_FD_84 | E4: lag 2 (lvl4) | F4: =COUNTIF('200V Devices'!E2:E393,A4) -> 110 | G4: =COUNTIFS('200V Devices'!E2:E393,A4,'200V Devices'!I2:I393,"To do") -> 0 | H4: 10.21.0.26 (ve 2000, VLAN 2000), from 26 Oct; was 192.168.122.21 (ve 100) | I4: Cutover done, 89 ports. system-max 40 active. Confirm APs online. Review tab change: 3/1/7, 3/1/28 to 2100 (no link). 1/1/48 left on 100. Confirm write memory. Unlisted AV: 8 ports 1230 -> 2700. 10 Oct: 6 outlets (20:7B:D2:30 devices) 1230 -> 2100. 10 Oct: 4/1/30 1230 -> 2700, 4/1/19 (Airtame) 1272 -> 2700, 3/1/1 (staff PC) 1240 -> 2100 | J4: Port clean-up: 54 ports (Trinity column Q, 16 Oct export). Management moved to 10.21.0.26, default route via 10.21.0.1, management source ve 2000, old IP removed. Saved. SmartZone HTTP 500 until old IP removed and agent restarted.
A5: switch-200V-stack-lv6 | B5: Access | C5: 7 x ICX8200 stack | D5: 3C_46_A1_07_54_4E | E5: lag 1 (lvl6) | F5: =COUNTIF('200V Devices'!E2:E393,A5) -> 167 | G5: =COUNTIFS('200V Devices'!E2:E393,A5,'200V Devices'!I2:I393,"To do") -> 0 | H5: 10.21.0.20 (ve 2000, VLAN 2000), from 26 Oct; was 192.168.122.11 (ve 100) | I5: Cutover done, 145 ports. system-max 40 active, STP on 2600/2700. Units 3/4 left the stack 20:03 and 22:44 on 9 Oct; out until unit 3 power cycled 13:35 on 10 Oct (unit 3 hangs; TAC/RMA). Saved. Review tab change: 8 ports to 2100. Saved | J5: Port clean-up: 144 ports (Trinity column Q, 16 Oct export). Management moved to 10.21.0.20, default route via 10.21.0.1, management source ve 2000, old IP removed. Saved. 1/1/32 had no MAC when checked.
A6: switch-200V-LT2-1 | B6: Access | C6: 1 x ICX8200-24P | D6: 3C_46_A1_05_28_AC | E6: lag 5 (LT01), LT2-1 ports 1/2/1-1/2/2 to core 1/1/5 + 2/1/5 (LLDP) | F6: =COUNTIF('200V Devices'!E2:E393,A6) -> 16 | G6: =COUNTIFS('200V Devices'!E2:E393,A6,'200V Devices'!I2:I393,"To do") -> 0 | H6: 10.21.0.21 (ve 2000, VLAN 2000), from 26 Oct; was 192.168.122.12 (ve 100) | I6: Cutover done, 16 ports. system-max 40 active | J6: Port clean-up: 5 ports (Trinity column Q, 16 Oct export). Management moved to 10.21.0.21, default route via 10.21.0.1, management source ve 2000, old IP removed. Saved.
A7: switch-200V-LT2-2 | B7: Access | C7: 1 x ICX7150-C12 | D7: 10_F0_68_0C_06_D6 | E7: Via LT2-1 port 1/1/23 (their 1/1/12), confirmed by LLDP | F7: =COUNTIF('200V Devices'!E2:E393,A7) -> 0 | G7: =COUNTIFS('200V Devices'!E2:E393,A7,'200V Devices'!I2:I393,"To do") -> 0 | H7: 10.21.0.22 (ve 2000, VLAN 2000), from 26 Oct; was 192.168.122.13 (ve 100) | I7: system-max 40 only; no port changes | J7: Port clean-up: 11 ports (Trinity column Q, 16 Oct export). Management moved to 10.21.0.22, default route via 10.21.0.1, management source ve 2000, old IP removed. Saved. 1/1/1 tagged-only with 2000-2953.
A8: switch-200V-LT2-3 | B8: Access | C8: 1 x ICX7150-C12 | D8: 10_F0_68_0B_D2_3E | E8: Via LT2-1 port 1/1/24 (their 1/1/12), confirmed by LLDP | F8: =COUNTIF('200V Devices'!E2:E393,A8) -> 0 | G8: =COUNTIFS('200V Devices'!E2:E393,A8,'200V Devices'!I2:I393,"To do") -> 0 | H8: 10.21.0.23 (ve 2000, VLAN 2000), from 26 Oct; was 192.168.122.14 (ve 100) | I8: system-max 40. Review tab change: 1/1/4 to 2100 (no link). Saved | J8: Port clean-up: 10 ports (Trinity column Q, 16 Oct export). Management moved to 10.21.0.23, default route via 10.21.0.1, management source ve 2000, old IP removed. Saved.
A9: switch-200V-8 | B9: Access | C9: 1 x ICX7150-C12 | D9: 10_F0_68_0B_D2_2C | E9: lag 4 (v08) | F9: =COUNTIF('200V Devices'!E2:E393,A9) -> 0 | G9: =COUNTIFS('200V Devices'!E2:E393,A9,'200V Devices'!I2:I393,"To do") -> 0 | H9: 10.21.0.25 (ve 2000, VLAN 2000), from 26 Oct; was 192.168.122.16 (ve 100) | I9: system-max 40 only; no port changes | J9: Port clean-up: 10 ports (Trinity column Q, 16 Oct export). Management moved to 10.21.0.25, default route via 10.21.0.1, management source ve 2000, old IP removed. Saved. UPS cards 1/1/7-1/1/9 to 2000 (DHCP); DNS servers added.
A10: switch-200V-Tutorial-6.03 | B10: Access | C10: 1 x ICX7150-C12 | D10: 10_F0_68_0B_D2_62 | E10: lag 6 (SW6.03) | F10: =COUNTIF('200V Devices'!E2:E393,A10) -> 6 | G10: =COUNTIFS('200V Devices'!E2:E393,A10,'200V Devices'!I2:I393,"To do") -> 0 | H10: 10.21.0.24 (ve 2000, VLAN 2000), from 26 Oct; was 192.168.122.15 (ve 100) | I10: Cutover done, 6 ports + 1/1/3 and 1/1/9 (added on site). system-max 40 active. Confirm write memory | J10: Port clean-up: 1 port (Trinity column Q, 16 Oct export). Management moved to 10.21.0.24, default route via 10.21.0.1, management source ve 2000, old IP removed. Saved.
A11: Total | F11: =SUM(F2:F10) -> 392 | G11: =SUM(G2:G10) -> 0
A13: Note: on 26 Oct 2026 the access switches' management moved from VLAN 100 (ve 100, 192.168.122.0/22) to VLAN 2000 (ve 2000, 10.21.0.20 - .27, gateway 10.21.0.1). The core stays on ve 1960 (10.20.8.2).

Sheet Port clean-up 26 Oct
A1: Port clean-up from Trinity's switch port export (16 Oct 2026, column Q), applied 26 Oct 2026 on all 8 switches
A3: Switch | B3: Port | C3: Old untagged VLAN | D3: Tagged VLANs removed | E3: New untagged VLAN | F3: Link 16 Oct | G3: MAC 16 Oct | H3: Note | I3: Status
A4: switch-200V-stack-lv6 | B4: 1/1/1 | C4: 1240 | D4: 1230, 1250, 1271, 1272, 1273 | E4: 2100 | F4: Down | I4: Done 26 Oct
A5: switch-200V-stack-lv6 | B5: 1/1/2 | C5: 1240 | D5: 1230, 1250, 1271, 1272, 1273 | E5: 2100 | F5: Down | I5: Done 26 Oct
A6: switch-200V-stack-lv6 | B6: 1/1/4 | C6: 1240 | D6: 1230, 1250, 1271, 1272, 1273 | E6: 2100 | F6: Down | I6: Done 26 Oct
A7: switch-200V-stack-lv6 | B7: 1/1/5 | C7: 1240 | D7: 1230, 1250, 1271, 1272, 1273 | E7: 2100 | F7: Down | I7: Done 26 Oct
A8: switch-200V-stack-lv6 | B8: 1/1/7 | C8: 1240 | D8: 1230, 1250, 1271, 1272, 1273 | E8: 2100 | F8: Down | I8: Done 26 Oct
A9: switch-200V-stack-lv6 | B9: 1/1/11 | C9: 1240 | D9: 1272, 1273 | E9: 2100 | F9: Down | I9: Done 26 Oct
A10: switch-200V-stack-lv6 | B10: 1/1/12 | C10: 1240 | D10: 1272, 1273 | E10: 2100 | F10: Down | I10: Done 26 Oct
A11: switch-200V-stack-lv6 | B11: 1/1/30 | C11: 1240 | D11: 1272, 1273 | E11: 2100 | F11: Down | I11: Done 26 Oct
A12: switch-200V-stack-lv6 | B12: 1/1/32 | C12: 1240 | D12: 1272, 1273 | E12: 2100 | F12: Up | G12: 1C:1A:DF:C2:4F:5E | I12: Done 26 Oct
A13: switch-200V-stack-lv6 | B13: 1/1/33 | C13: 1240 | D13: 1272, 1273 | E13: 2100 | F13: Down | I13: Done 26 Oct
A14: switch-200V-stack-lv6 | B14: 1/1/34 | C14: 1240 | D14: 1272, 1273 | E14: 2100 | F14: Down | I14: Done 26 Oct
A15: switch-200V-stack-lv6 | B15: 1/1/35 | C15: 100 | D15: 1212, 1213, 1230, 1240, 1250, 1271, 1272, 1273 | E15: 1 (default) | F15: Down | I15: Done 26 Oct
A16: switch-200V-stack-lv6 | B16: 1/1/36 | C16: 1240 | D16: 1272, 1273 | E16: 2100 | F16: Down | I16: Done 26 Oct
A17: switch-200V-stack-lv6 | B17: 1/1/41 | C17: 1240 | D17: 1272, 1273 | E17: 2100 | F17: Down | I17: Done 26 Oct
A18: switch-200V-stack-lv6 | B18: 1/1/42 | C18: 1240 | D18: 1272, 1273 | E18: 2100 | F18: Down | I18: Done 26 Oct
A19: switch-200V-stack-lv6 | B19: 1/1/43 | C19: 1240 | D19: 1272, 1273 | E19: 2100 | F19: Up | G19: A0:4A:5E:E7:E8:70 | I19: Done 26 Oct
A20: switch-200V-stack-lv6 | B20: 1/1/44 | C20: 1240 | D20: 1272, 1273 | E20: 2100 | F20: Down | I20: Done 26 Oct
A21: switch-200V-stack-lv6 | B21: 1/1/45 | C21: 1240 | D21: 1272 | E21: 2100 | F21: Down | I21: Done 26 Oct
A22: switch-200V-stack-lv6 | B22: 1/1/46 | C22: 1240 | D22: 1272, 1273 | E22: 2100 | F22: Down | I22: Done 26 Oct
A23: switch-200V-stack-lv6 | B23: 1/1/47 | C23: 1240 | D23: 1273 | E23: 2100 | F23: Down | I23: Done 26 Oct
A24: switch-200V-stack-lv6 | B24: 1/1/48 | C24: 1240 | E24: 2100 | F24: Down | I24: Done 26 Oct
A25: switch-200V-stack-lv6 | B25: 2/1/4 | C25: 1240 | E25: 2100 | F25: Down | I25: Done 26 Oct
A26: switch-200V-stack-lv6 | B26: 2/1/5 | C26: 1240 | E26: 2100 | F26: Down | I26: Done 26 Oct
A27: switch-200V-stack-lv6 | B27: 2/1/6 | C27: 1240 | E27: 2100 | F27: Up | G27: 1C:1A:DF:C2:51:28 | I27: Done 26 Oct
A28: switch-200V-stack-lv6 | B28: 2/1/7 | C28: 1240 | E28: 2100 | F28: Down | I28: Done 26 Oct
A29: switch-200V-stack-lv6 | B29: 2/1/8 | C29: 1240 | E29: 2100 | F29: Down | I29: Done 26 Oct
A30: switch-200V-stack-lv6 | B30: 2/1/9 | C30: 1240 | E30: 2100 | F30: Down | I30: Done 26 Oct
A31: switch-200V-stack-lv6 | B31: 2/1/10 | C31: 1240 | E31: 2100 | F31: Down | I31: Done 26 Oct
A32: switch-200V-stack-lv6 | B32: 2/1/11 | C32: 1240 | E32: 2100 | F32: Down | I32: Done 26 Oct
A33: switch-200V-stack-lv6 | B33: 2/1/12 | C33: 1240 | E33: 2100 | F33: Down | I33: Done 26 Oct
A34: switch-200V-stack-lv6 | B34: 2/1/13 | C34: 1240 | E34: 2100 | F34: Down | I34: Done 26 Oct
A35: switch-200V-stack-lv6 | B35: 2/1/48 | C35: 1240 | E35: 2100 | F35: Down | I35: Done 26 Oct
A36: switch-200V-stack-lv6 | B36: 3/1/2 | C36: 1230 | E36: 1 (default) | F36: Down | I36: Done 26 Oct
A37: switch-200V-stack-lv6 | B37: 3/1/3 | C37: 1240 | E37: 2100 | F37: Down | I37: Done 26 Oct
A38: switch-200V-stack-lv6 | B38: 3/1/4 | C38: 1240 | E38: 2100 | F38: Down | I38: Done 26 Oct
A39: switch-200V-stack-lv6 | B39: 3/1/5 | C39: 1240 | E39: 2100 | F39: Down | I39: Done 26 Oct
A40: switch-200V-stack-lv6 | B40: 3/1/6 | C40: 1240 | E40: 2100 | F40: Up | G40: 1C:1A:DF:C2:51:01 | I40: Done 26 Oct
A41: switch-200V-stack-lv6 | B41: 3/1/7 | C41: 1240 | E41: 2100 | F41: Up | G41: 1C:1A:DF:C0:98:69 | I41: Done 26 Oct
...

Sheet Ports without device
A1: Switch name | B1: Port | C1: Untagged VLAN | D1: New VLAN | E1: Tagged VLANs | F1: MACs seen (200V tab) | G1: MAC(s) seen | H1: Note
A2: switch-200V-8 | B2: 1/1/1 | C2: 1240 (200V_staff) | D2: 2100 (VL-staff-wired-01) | F2: 0
A3: switch-200V-8 | B3: 1/1/2 | C3: 1240 (200V_staff) | D3: 2100 (VL-staff-wired-01) | F3: 0
A4: switch-200V-8 | B4: 1/1/3 | C4: 1240 (200V_staff) | D4: 2100 (VL-staff-wired-01) | F4: 0
A5: switch-200V-8 | B5: 1/1/4 | C5: 1240 (200V_staff) | D5: 2100 (VL-staff-wired-01) | F5: 0
A6: switch-200V-8 | B6: 1/1/5 | C6: 1240 (200V_staff) | D6: 2100 (VL-staff-wired-01) | F6: 0
A7: switch-200V-8 | B7: 1/1/6 | C7: 1230 (200V_av) | D7: 2700 (VL-av-01) | F7: 0
A8: switch-200V-8 | B8: 1/1/7 | C8: 1240 (200V_staff) | D8: 2100 (VL-staff-wired-01) | F8: 0
A9: switch-200V-8 | B9: 1/1/8 | C9: 1240 (200V_staff) | D9: 2100 (VL-staff-wired-01) | F9: 0
A10: switch-200V-8 | B10: 1/1/9 | C10: 1240 (200V_staff) | D10: 2100 (VL-staff-wired-01) | F10: 0
A11: switch-200V-8 | B11: 1/1/10 | C11: 1240 (200V_staff) | D11: 2100 (VL-staff-wired-01) | F11: 0
A12: switch-200V-8 | B12: 1/1/11 | C12: 1240 (200V_staff) | D12: 2100 (VL-staff-wired-01) | F12: 0
A13: switch-200V-8 | B13: 1/1/12 | C13: None (tagged only) | D13: n/a (trunk) | E13: 100,1212,1213,1230,1240,1250,1271,1272,1273,2000,2010,2020,2100,2200,2300,2310,2320,2400,2500,2510,2520,2530,2600,2700,2800,2810,2900 | F13: 0 | H13: Trunk/uplink: tagged VLANs only
A14: switch-200V-LT2-1 | B14: 1/1/2 | C14: 100 (management) | D14: 2010 (VL-wifimgmt-01) | E14: 1212,1213,1230,1240,1250,1271,1272,1273 | F14: 0
A15: switch-200V-LT2-1 | B15: 1/1/3 | C15: 1230 (200V_av) | D15: 2700 (VL-av-01) | F15: 0
A16: switch-200V-LT2-1 | B16: 1/1/9 | C16: 1230 (200V_av) | D16: 2700 (VL-av-01) | F16: 1 | G16: 00:50:56:05:43:F1
A17: switch-200V-LT2-1 | B17: 1/1/19 | C17: 1230 (200V_av) | D17: 2700 (VL-av-01) | F17: 0
A18: switch-200V-LT2-1 | B18: 1/1/21 | C18: 1240 (200V_staff) | D18: 2100 (VL-staff-wired-01) | F18: 1 | G18: 48:21:0B:56:AC:A4 | H18: LLDP: CLA-TAN3130059J (NUC, MAC 48:21:0B:56:AC:A4), not in device list
A19: switch-200V-LT2-1 | B19: 1/1/22 | C19: 1230 (200V_av) | D19: 2700 (VL-av-01) | F19: 0
A20: switch-200V-LT2-1 | B20: 1/1/23 | C20: None (tagged only) | D20: n/a (trunk) | E20: 100,1212,1213,1230,1240,1250,1271,1272,1273,2000,2010,2020,2100,2200,2300,2310,2320,2400,2500,2510,2520,2530,2600,2700,2800,2810,2900,2950,2951,2952,2953 | F20: 2 | G20: 10:F0:68:0C:06:E1, 10:F0:68:0C:06:D6 | H20: Uplink to switch-200V-LT2-2 (LLDP)
A21: switch-200V-LT2-1 | B21: 1/1/24 | C21: None (tagged only) | D21: n/a (trunk) | E21: 100,1212,1213,1230,1240,1250,1271,1272,1273,2000,2010,2020,2100,2200,2300,2310,2320,2400,2500,2510,2520,2530,2600,2700,2800,2810,2900,2950,2951,2952,2953 | F21: 3 | G21: 10:F0:68:0B:D2:49, 10:F0:68:0B:D2:3E, AC:B4:80:F1:61:7F | H21: Uplink to switch-200V-LT2-3 (LLDP)
A22: switch-200V-LT2-2 | B22: 1/1/1 | C22: 1240 (200V_staff) | D22: 2100 (VL-staff-wired-01) | E22: 1212,1213,1230,1250,1271,1272,1273,2000,2010,2020,2100,2200,2300,2310,2320,2400,2500,2510,2520,2530,2600,2700,2800,2810,2900,2950,2951,2952,2953 | F22: 0
A23: switch-200V-LT2-2 | B23: 1/1/2 | C23: 1240 (200V_staff) | D23: 2100 (VL-staff-wired-01) | F23: 0
A24: switch-200V-LT2-2 | B24: 1/1/3 | C24: 1240 (200V_staff) | D24: 2100 (VL-staff-wired-01) | F24: 0
A25: switch-200V-LT2-2 | B25: 1/1/4 | C25: 1240 (200V_staff) | D25: 2100 (VL-staff-wired-01) | F25: 0
A26: switch-200V-LT2-2 | B26: 1/1/5 | C26: 1240 (200V_staff) | D26: 2100 (VL-staff-wired-01) | F26: 0
A27: switch-200V-LT2-2 | B27: 1/1/6 | C27: 1240 (200V_staff) | D27: 2100 (VL-staff-wired-01) | F27: 0
A28: switch-200V-LT2-2 | B28: 1/1/7 | C28: 1240 (200V_staff) | D28: 2100 (VL-staff-wired-01) | F28: 0
A29: switch-200V-LT2-2 | B29: 1/1/8 | C29: 1240 (200V_staff) | D29: 2100 (VL-staff-wired-01) | F29: 0
A30: switch-200V-LT2-2 | B30: 1/1/9 | C30: 1240 (200V_staff) | D30: 2100 (VL-staff-wired-01) | F30: 0
A31: switch-200V-LT2-2 | B31: 1/1/10 | C31: 1240 (200V_staff) | D31: 2100 (VL-staff-wired-01) | F31: 0
A32: switch-200V-LT2-2 | B32: 1/1/11 | C32: 1240 (200V_staff) | D32: 2100 (VL-staff-wired-01) | F32: 0
A33: switch-200V-LT2-2 | B33: 1/1/12 | C33: None (tagged only) | D33: n/a (trunk) | E33: 100,1212,1213,1230,1240,1250,1271,1272,1273,2000,2010,2020,2100,2200,2300,2310,2320,2400,2500,2510,2520,2530,2600,2700,2800,2810,2900,2950,2951,2952,2953 | F33: 0 | H33: Trunk/uplink: tagged VLANs only
A34: switch-200V-LT2-3 | B34: 1/1/1 | C34: 1240 (200v_staff) | D34: 2100 (VL-staff-wired-01) | E34: 100 | F34: 0
A35: switch-200V-LT2-3 | B35: 1/1/2 | C35: 1240 (200v_staff) | D35: 2100 (VL-staff-wired-01) | E35: 100 | F35: 0
A36: switch-200V-LT2-3 | B36: 1/1/3 | C36: 1240 (200v_staff) | D36: 2100 (VL-staff-wired-01) | E36: 100 | F36: 0
A37: switch-200V-LT2-3 | B37: 1/1/4 | C37: 1240 (200v_staff) | D37: 2100 (VL-staff-wired-01) | E37: 100 | F37: 1 | G37: d4:a2:cd:e1:dd:0e | H37: Moved 9 Oct (Review tab change).
A38: switch-200V-LT2-3 | B38: 1/1/5 | C38: 1240 (200v_staff) | D38: 2100 (VL-staff-wired-01) | E38: 100 | F38: 0
A39: switch-200V-LT2-3 | B39: 1/1/6 | C39: 1240 (200v_staff) | D39: 2100 (VL-staff-wired-01) | E39: 100 | F39: 0
A40: switch-200V-LT2-3 | B40: 1/1/7 | C40: 1240 (200v_staff) | D40: 2100 (VL-staff-wired-01) | E40: 100 | F40: 0
...

Sheet Not found
A1: Master row | B1: Type | C1: Device | D1: MAC | E1: Old VLAN | F1: New VLAN | G1: Reason
A2: 475 | B2: AP | C2: r650-39-4d-10 | D2: C8:A6:08:39:4D:10 | E2: 100 (management) | F2: 2010 (VL-wifimgmt-01) | G2: MAC not in 200V tab
A3: 769 | B3: AV | C3: AV Switcher | D3: 00:1D:56:0A:DF:C0 | E3: Unknown | F3: 2700 (VL-av-01) | G3: MAC not in 200V tab
A4: 779 | B4: AV | C4: AV Switcher | D4: 00-1D-56-0A-B4-AB | E4: Unknown | F4: 2700 (VL-av-01) | G4: MAC not in 200V tab
A5: 1121 | B5: AV | C5: Projector | D5: F8:25:51:72:A4:52 | E5: Unknown | F5: 2700 (VL-av-01) | G5: MAC not in 200V tab
A6: 1134 | B6: AV | C6: Projector | D6: F8:25:51:CB:8C:94 | E6: Unknown | F6: 2700 (VL-av-01) | G6: MAC not in 200V tab
A7: 1145 | B7: AV | C7: Projector | D7: F8:25:51:CC:0F:C6 | E7: Unknown | F7: 2700 (VL-av-01) | G7: MAC not in 200V tab

Sheet Summary
A1: Source | B1: Devices master list, Devices tab, Location = 200V
A3: Devices with a port | B3: =COUNTA('200V Devices'!C2:C393) -> 392
A4: Done (pilot) | B4: =COUNTIF('200V Devices'!I2:I393,"Done (pilot)") -> 39
A5: Done (9 Oct cutover) | B5: =COUNTIF('200V Devices'!I2:I393,"Done") -> 353
A6: To do | B6: =COUNTIF('200V Devices'!I2:I393,"To do") -> 0
A7: Port matched from 200V tab (check) | B7: =COUNTIF('200V Devices'!J2:J393,"Matched from 200V tab") -> 14
A8: Not found on any switch | B8: =COUNTA('Not found'!C2:C7) -> 6
A9: Total 200V devices | B9: =B3+B8 -> 398
A11: Switch | B11: Devices
A12: switch-200V-LT2-1 | B12: =COUNTIF('200V Devices'!E2:E393,"switch-200V-LT2-1") -> 16
A13: switch-200V-Tutorial-6.03 | B13: =COUNTIF('200V Devices'!E2:E393,"switch-200V-Tutorial-6.03") -> 6
A14: switch-200V-stack-lv3 | B14: =COUNTIF('200V Devices'!E2:E393,"switch-200V-stack-lv3") -> 93
A15: switch-200V-stack-lv4 | B15: =COUNTIF('200V Devices'!E2:E393,"switch-200V-stack-lv4") -> 110
A16: switch-200V-stack-lv6 | B16: =COUNTIF('200V Devices'!E2:E393,"switch-200V-stack-lv6") -> 167
A18: Legend
A19: Green row | B19: Moved in the 5 October pilot or the 9 October cutover (yellow rows were also moved)
A20: Yellow row | B20: Master list lookup failed; switch and port taken from the 200V tab by MAC
A22: Ports with a VLAN but no device listed | B22: =COUNTA('Ports without device'!A2:A362) -> 361
A23: MAC seen on port (orange) | B23: =COUNTIF('Ports without device'!F2:F362,">0") -> 45
A24: No MAC seen | B24: =COUNTIF('Ports without device'!F2:F362,0) -> 316
A25: Pilot staff outlets (green) | B25: =COUNTIF('Ports without device'!H2:H362,"Pilot staff outlet*") -> 22
A26: Trunk / uplink ports (grey) | B26: =COUNTIF('Ports without device'!C2:C362,"None (tagged only)") -> 12
A27: Orange row | B27: Ports without device tab: a MAC was seen on the port but no device is listed
A29: Review items | B29: =COUNT(Review!A5:A130) -> 112
A30: Decided | B30: =COUNTA(Review!H5:H130) -> 51
A31: Open | B31: =B29-B30 -> 61
